Workbook
Name BrandList: BrandCOOs!$A$2:$A$28
Name COOs: USA_Costs!$B$2:$B$9
Name DestinationZones: PostalCost_International!$A$2:$A$24
Name WeightBand: PostalCost_International!$G$3:$G$7
Name WeightRanges: PostalCost_International!$C$3:$C$7
Name ZonosProcessingChargeCostPerShipment: USA_Costs!$B$12
Name ZonosProcessingChargePercentage: USA_Costs!$B$11

Sheet 🌟 Lookup Calculator 🐵
C1: 🌟👑 La Troverie - International Shipping + Duties Calculator 👑🌟
C3: Item Value (AUD) | D3: 125
C4: Weight | D4: Medium [500 - 1kg]
C5: Brand | D5: Kip & Co
C6: Destination Zone | D6: 3-USA & Canada
C7: Excess Cover (Insured) | D7: No | E7: =IF(AND($D$3>=250,$D$7<>"Yes"),"⚠️ WARNING - Insurance Recommended as Value is over $250 threshold [Maximum Default AusPost cover is $100]",IF(AND($D$3<250,$D$7<>"No"),"⚠️ WARNING - Insurance NOT Recommended as Value is under $250 threshold [Maximum Default AusPost cover is $100]",""))
C10: Auspost Shipping | D10: =$D$6 -> 3-USA & Canada | E10: 1 | F10: 2 | G10: 3 | H10: 4 | I10: 5
C11: Standard | D11: =_xlfn.XLOOKUP(D4,WeightRanges,WeightBand,"ERR: Cannot match weight to band",0,1) -> Medium | E11: =_xlfn.XLOOKUP($D$6&"::"&$D$11,PostalCost_International!$B$2:$B$24,PostalCost_International!K2:K24) -> 40.8918 | F11: =_xlfn.XLOOKUP($D$6&"::"&$D$11,PostalCost_International!$B$2:$B$24,PostalCost_International!L2:L24) -> 36.5874 | G11: =_xlfn.XLOOKUP($D$6&"::"&$D$11,PostalCost_International!$B$2:$B$24,PostalCost_International!M2:M24) -> 35.5113 | H11: =_xlfn.XLOOKUP($D$6&"::"&$D$11,PostalCost_International!$B$2:$B$24,PostalCost_International!N2:N24) -> 34.4352 | I11: =_xlfn.XLOOKUP($D$6&"::"&$D$11,PostalCost_International!$B$2:$B$24,PostalCost_International!O2:O24) -> 33.3591
C12: Extra Cover | E12: =($D3-100)/100*'Extra Cover'!$B$3*(1-'Extra Cover'!C$3) -> 0.6 | F12: =($D3-100)/100*'Extra Cover'!$B$3*(1-'Extra Cover'!D$3) -> 0.6 | G12: =($D3-100)/100*'Extra Cover'!$B$3*(1-'Extra Cover'!E$3) -> 0.6 | H12: =($D3-100)/100*'Extra Cover'!$B$3*(1-'Extra Cover'!F$3) -> 0.6 | I12: =($D3-100)/100*'Extra Cover'!$B$3*(1-'Extra Cover'!G$3) -> 0.6
C13: ="Subtotal "&IF(D7="No","[ No Excess Cover/Insurance ]"," [ With Excess Cover/Insurance ]") -> Subtotal [ No Excess Cover/Insurance ] | E13: =IF($D$7="Yes",SUM(E11:E12),E11) -> 40.8918 | F13: =IF($D$7="Yes",SUM(F11:F12),F11) -> 36.5874 | G13: =IF($D$7="Yes",SUM(G11:G12),G11) -> 35.5113 | H13: =IF($D$7="Yes",SUM(H11:H12),H11) -> 34.4352 | I13: =IF($D$7="Yes",SUM(I11:I12),I11) -> 33.3591
C16: US Customs & Duties | D16: Country of Origin/Manufacture | E16: =_xlfn.XLOOKUP(D5,BrandCOOs!A2:A28,BrandCOOs!C2:C28,"ERR: Cannot match brand to COO",0,1) -> India
C17: Tariffs | D17: =_xlfn.XLOOKUP(E16,COOs,USA_Costs!C2:C9,"⚠️ ERR: Cannot match COO to Duty Cost",0,1) -> 0.5 | F17: =D3*D17 -> 62.5
C18: Zonos Charges | F18: =(F17*ZonosProcessingChargePercentage)+ZonosProcessingChargeCostPerShipment -> 7.94
C19: Subtotal | F19: =SUM(F17:F18) -> 70.44
C21: ="Total Shipping"&CHAR(10)&IF(D7="No","[ No Excess Cover/Insurance ]","[ With Excess Cover/Insurance ]") -> Total Shipping [ No Excess Cover/Insurance ] | E21: =E13+IF($D$6="3-USA & Canada",$F$19,0) -> 111.3318 | F21: =F13+IF($D$6="3-USA & Canada",$F$19,0) -> 107.0274 | G21: =G13+IF($D$6="3-USA & Canada",$F$19,0) -> 105.9513 | H21: =H13+IF($D$6="3-USA & Canada",$F$19,0) -> 104.8752 | I21: =I13+IF($D$6="3-USA & Canada",$F$19,0) -> 103.7991

Sheet PostalCost_International
A1: DestinationCode | B1: DestinationAndWeightMatch | C1: WeightRangeCode | D1: Zone | E1: Region | F1: Service | G1: Weight Band | H1: Weight | I1: Band 0 (Base) | J1: Handling Fee | K1: Band 1 | L1: Band 2 | M1: Band 3 | N1: Band 4 | O1: Band 5 | Q1: https://auspost.com.au/content/dam/auspost_corp/media/documents/mypost-business-postage-rates-guide.pdf
A2: =IF(ISBLANK(D2),"",D2&"-"&E2) -> 3-USA & Canada | B2: =IF(ISBLANK(G2),"",A2&"::"&G2) | D2: 3 | E2: USA & Canada | J2: 0.02 | K2: 0.05 | L2: 0.15 | M2: 0.175 | N2: 0.2 | O2: 0.225
A3: =IF(ISBLANK(D3),"",D3&"-"&E3) -> 3-USA & Canada | B3: =IF(ISBLANK(G3),"",A3&"::"&G3) -> 3-USA & Canada::XSmall | C3: =IF(ISBLANK(G3),"",G3&" ["&H3&"]") -> XSmall [< 250g] | D3: 3 | E3: USA & Canada | F3: Standard | G3: XSmall | H3: < 250g | I3: 22.3 | J3: =I3*(1+J$2) -> 22.746 | K3: =$J3*(1-K$2) -> 21.6087 | L3: =$J3*(1-L$2) -> 19.3341 | M3: =$J3*(1-M$2) -> 18.76545 | N3: =$J3*(1-N$2) -> 18.1968 | O3: =$J3*(1-O$2) -> 17.62815
A4: =IF(ISBLANK(D4),"",D4&"-"&E4) -> 3-USA & Canada | B4: =IF(ISBLANK(G4),"",A4&"::"&G4) -> 3-USA & Canada::Small | C4: =IF(ISBLANK(G4),"",G4&" ["&H4&"]") -> Small [250 - 500g] | D4: 3 | E4: USA & Canada | F4: Standard | G4: Small | H4: 250 - 500g | I4: 29 | J4: =I4*(1+J$2) -> 29.58 | K4: =$J4*(1-K$2) -> 28.101 | L4: =$J4*(1-L$2) -> 25.143 | M4: =$J4*(1-M$2) -> 24.4035 | N4: =$J4*(1-N$2) -> 23.664 | O4: =$J4*(1-O$2) -> 22.9245
A5: =IF(ISBLANK(D5),"",D5&"-"&E5) -> 3-USA & Canada | B5: =IF(ISBLANK(G5),"",A5&"::"&G5) -> 3-USA & Canada::Medium | C5: =IF(ISBLANK(G5),"",G5&" ["&H5&"]") -> Medium [500 - 1kg] | D5: 3 | E5: USA & Canada | F5: Standard | G5: Medium | H5: 500 - 1kg | I5: 42.2 | J5: =I5*(1+J$2) -> 43.044 | K5: =$J5*(1-K$2) -> 40.8918 | L5: =$J5*(1-L$2) -> 36.5874 | M5: =$J5*(1-M$2) -> 35.5113 | N5: =$J5*(1-N$2) -> 34.4352 | O5: =$J5*(1-O$2) -> 33.3591
A6: =IF(ISBLANK(D6),"",D6&"-"&E6) -> 3-USA & Canada | B6: =IF(ISBLANK(G6),"",A6&"::"&G6) -> 3-USA & Canada::Large | C6: =IF(ISBLANK(G6),"",G6&" ["&H6&"]") -> Large [1 - 1.5kg] | D6: 3 | E6: USA & Canada | F6: Standard | G6: Large | H6: 1 - 1.5kg | I6: 55.55 | J6: =I6*(1+J$2) -> 56.661 | K6: =$J6*(1-K$2) -> 53.82795 | L6: =$J6*(1-L$2) -> 48.16185 | M6: =$J6*(1-M$2) -> 46.745325 | N6: =$J6*(1-N$2) -> 45.3288 | O6: =$J6*(1-O$2) -> 43.912275
A7: =IF(ISBLANK(D7),"",D7&"-"&E7) -> 3-USA & Canada | B7: =IF(ISBLANK(G7),"",A7&"::"&G7) -> 3-USA & Canada::XLarge | C7: =IF(ISBLANK(G7),"",G7&" ["&H7&"]") -> XLarge [1.5kg - 2kg] | D7: 3 | E7: USA & Canada | F7: Standard | G7: XLarge | H7: 1.5kg - 2kg | I7: 68.85 | J7: =I7*(1+J$2) -> 70.227 | K7: =$J7*(1-K$2) -> 66.71565 | L7: =$J7*(1-L$2) -> 59.69295 | M7: =$J7*(1-M$2) -> 57.937275 | N7: =$J7*(1-N$2) -> 56.1816 | O7: =$J7*(1-O$2) -> 54.425925
A8: =IF(ISBLANK(D8),"",D8&"-"&E8) -> 4-UK & Ireland | B8: =IF(ISBLANK(G8),"",A8&"::"&G8) | C8: =IF(ISBLANK(G8),"",G8&" ["&H8&"]") | D8: 4 | E8: UK & Ireland | J8: 0.02 | K8: 0.05 | L8: 0.15 | M8: 0.175 | N8: 0.2 | O8: 0.225
A9: =IF(ISBLANK(D9),"",D9&"-"&E9) -> 4-UK & Ireland | B9: =IF(ISBLANK(G9),"",A9&"::"&G9) -> 4-UK & Ireland::XSmall | C9: =IF(ISBLANK(G9),"",G9&" ["&H9&"]") -> XSmall [< 250g] | D9: 4 | E9: UK & Ireland | F9: Standard | G9: XSmall | H9: < 250g | I9: 27.5 | J9: =I9*(1+J$8) -> 28.05 | K9: =$J9*(1-K$8) -> 26.6475 | L9: =$J9*(1-L$8) -> 23.8425 | M9: =$J9*(1-M$8) -> 23.14125 | N9: =$J9*(1-N$8) -> 22.44 | O9: =$J9*(1-O$8) -> 21.73875
A10: =IF(ISBLANK(D10),"",D10&"-"&E10) -> 4-UK & Ireland | B10: =IF(ISBLANK(G10),"",A10&"::"&G10) -> 4-UK & Ireland::Small | C10: =IF(ISBLANK(G10),"",G10&" ["&H10&"]") -> Small [250 - 500g] | D10: 4 | E10: UK & Ireland | F10: Standard | G10: Small | H10: 250 - 500g | I10: =34.4 -> 34.4 | J10: =I10*(1+J$8) -> 35.088 | K10: =$J10*(1-K$8) -> 33.3336 | L10: =$J10*(1-L$8) -> 29.8248 | M10: =$J10*(1-M$8) -> 28.9476 | N10: =$J10*(1-N$8) -> 28.0704 | O10: =$J10*(1-O$8) -> 27.1932
A11: =IF(ISBLANK(D11),"",D11&"-"&E11) -> 4-UK & Ireland | B11: =IF(ISBLANK(G11),"",A11&"::"&G11) -> 4-UK & Ireland::Medium | C11: =IF(ISBLANK(G11),"",G11&" ["&H11&"]") -> Medium [500 - 1kg] | D11: 4 | E11: UK & Ireland | F11: Standard | G11: Medium | H11: 500 - 1kg | I11: 48.3 | J11: =I11*(1+J$8) -> 49.266 | K11: =$J11*(1-K$8) -> 46.8027 | L11: =$J11*(1-L$8) -> 41.8761 | M11: =$J11*(1-M$8) -> 40.64445 | N11: =$J11*(1-N$8) -> 39.4128 | O11: =$J11*(1-O$8) -> 38.18115
A12: =IF(ISBLANK(D12),"",D12&"-"&E12) -> 4-UK & Ireland | B12: =IF(ISBLANK(G12),"",A12&"::"&G12) -> 4-UK & Ireland::Large | C12: =IF(ISBLANK(G12),"",G12&" ["&H12&"]") -> Large [1 - 1.5kg] | D12: 4 | E12: UK & Ireland | F12: Standard | G12: Large | H12: 1 - 1.5kg | I12: 62.15 | J12: =I12*(1+J$8) -> 63.393 | K12: =$J12*(1-K$8) -> 60.22335 | L12: =$J12*(1-L$8) -> 53.88405 | M12: =$J12*(1-M$8) -> 52.299225 | N12: =$J12*(1-N$8) -> 50.7144 | O12: =$J12*(1-O$8) -> 49.129575
D13: 4 | E13: UK & Ireland | F13: Standard | G13: XLarge | H13: 1.5kg - 2kg | I13: 76 | J13: =I13*(1+J$8) -> 77.52 | K13: =$J13*(1-K$8) -> 73.644 | L13: =$J13*(1-L$8) -> 65.892 | M13: =$J13*(1-M$8) -> 63.954 | N13: =$J13*(1-N$8) -> 62.016 | O13: =$J13*(1-O$8) -> 60.078
A14: =IF(ISBLANK(D14),"",D14&"-"&E14) -> 4-Major EU | B14: =IF(ISBLANK(G14),"",A14&"::"&G14) | C14: =IF(ISBLANK(G14),"",G14&" ["&H14&"]") | D14: 4 | E14: Major EU | J14: 0.02 | K14: 0.05 | L14: 0.1 | M14: 0.125 | N14: 0.15 | O14: 0.175
A15: =IF(ISBLANK(D15),"",D15&"-"&E15) -> 4-Major EU | B15: =IF(ISBLANK(G15),"",A15&"::"&G15) -> 4-Major EU::XSmall | C15: =IF(ISBLANK(G15),"",G15&" ["&H15&"]") -> XSmall [< 250g] | D15: 4 | E15: Major EU | F15: Standard | G15: XSmall | H15: < 250g | I15: 27.5 | J15: =I15*(1+J$14) -> 28.05 | K15: =$J15*(1-K$14) -> 26.6475 | L15: =$J15*(1-L$14) -> 25.245 | M15: =$J15*(1-M$14) -> 24.54375 | N15: =$J15*(1-N$14) -> 23.8425 | O15: =$J15*(1-O$14) -> 23.14125
A16: =IF(ISBLANK(D16),"",D16&"-"&E16) -> 4-Major EU | B16: =IF(ISBLANK(G16),"",A16&"::"&G16) -> 4-Major EU::Small | C16: =IF(ISBLANK(G16),"",G16&" ["&H16&"]") -> Small [250 - 500g] | D16: 4 | E16: Major EU | F16: Standard | G16: Small | H16: 250 - 500g | I16: =34.4 -> 34.4 | J16: =I16*(1+J$14) -> 35.088 | K16: =$J16*(1-K$14) -> 33.3336 | L16: =$J16*(1-L$14) -> 31.5792 | M16: =$J16*(1-M$14) -> 30.702 | N16: =$J16*(1-N$14) -> 29.8248 | O16: =$J16*(1-O$14) -> 28.9476
A17: =IF(ISBLANK(D17),"",D17&"-"&E17) -> 4-Major EU | B17: =IF(ISBLANK(G17),"",A17&"::"&G17) -> 4-Major EU::Medium | C17: =IF(ISBLANK(G17),"",G17&" ["&H17&"]") -> Medium [500 - 1kg] | D17: 4 | E17: Major EU | F17: Standard | G17: Medium | H17: 500 - 1kg | I17: 48.3 | J17: =I17*(1+J$14) -> 49.266 | K17: =$J17*(1-K$14) -> 46.8027 | L17: =$J17*(1-L$14) -> 44.3394 | M17: =$J17*(1-M$14) -> 43.10775 | N17: =$J17*(1-N$14) -> 41.8761 | O17: =$J17*(1-O$14) -> 40.64445
A18: =IF(ISBLANK(D18),"",D18&"-"&E18) -> 4-Major EU | B18: =IF(ISBLANK(G18),"",A18&"::"&G18) -> 4-Major EU::Large | C18: =IF(ISBLANK(G18),"",G18&" ["&H18&"]") -> Large [1 - 1.5kg] | D18: 4 | E18: Major EU | F18: Standard | G18: Large | H18: 1 - 1.5kg | I18: 62.15 | J18: =I18*(1+J$14) -> 63.393 | K18: =$J18*(1-K$14) -> 60.22335 | L18: =$J18*(1-L$14) -> 57.0537 | M18: =$J18*(1-M$14) -> 55.468875 | N18: =$J18*(1-N$14) -> 53.88405 | O18: =$J18*(1-O$14) -> 52.299225
D19: 4 | E19: Major EU | F19: Standard | G19: XLarge | H19: 1.5kg - 2kg | I19: 76 | J19: =I19*(1+J$14) -> 77.52 | K19: =$J19*(1-K$14) -> 73.644 | L19: =$J19*(1-L$14) -> 69.768 | M19: =$J19*(1-M$14) -> 67.83 | N19: =$J19*(1-N$14) -> 65.892 | O19: =$J19*(1-O$14) -> 63.954
A20: =IF(ISBLANK(D20),"",D20&"-"&E20) -> 1-New Zealand | B20: =IF(ISBLANK(G20),"",A20&"::"&G20) | C20: =IF(ISBLANK(G20),"",G20&" ["&H20&"]") | D20: 1 | E20: New Zealand | J20: 0.02 | K20: 0.05 | L20: 0.2 | M20: 0.25 | N20: 0.3 | O20: 0.35
A21: =IF(ISBLANK(D21),"",D21&"-"&E21) -> 1-New Zealand | B21: =IF(ISBLANK(G21),"",A21&"::"&G21) -> 1-New Zealand::XSmall | C21: =IF(ISBLANK(G21),"",G21&" ["&H21&"]") -> XSmall [< 250g] | D21: 1 | E21: New Zealand | F21: Standard | G21: XSmall | H21: < 250g | I21: 16.3 | J21: =I21*(1+J$20) -> 16.626 | K21: =$J21*(1-K$20) -> 15.7947 | L21: =$J21*(1-L$20) -> 13.3008 | M21: =$J21*(1-M$20) -> 12.4695 | N21: =$J21*(1-N$20) -> 11.6382 | O21: =$J21*(1-O$20) -> 10.8069
A22: =IF(ISBLANK(D22),"",D22&"-"&E22) -> 1-New Zealand | B22: =IF(ISBLANK(G22),"",A22&"::"&G22) -> 1-New Zealand::Small | C22: =IF(ISBLANK(G22),"",G22&" ["&H22&"]") -> Small [250 - 500g] | D22: 1 | E22: New Zealand | F22: Standard | G22: Small | H22: 250 - 500g | I22: 19.65 | J22: =I22*(1+J$20) -> 20.043 | K22: =$J22*(1-K$20) -> 19.04085 | L22: =$J22*(1-L$20) -> 16.0344 | M22: =$J22*(1-M$20) -> 15.03225 | N22: =$J22*(1-N$20) -> 14.0301 | O22: =$J22*(1-O$20) -> 13.02795
A23: =IF(ISBLANK(D23),"",D23&"-"&E23) -> 1-New Zealand | B23: =IF(ISBLANK(G23),"",A23&"::"&G23) -> 1-New Zealand::Medium | C23: =IF(ISBLANK(G23),"",G23&" ["&H23&"]") -> Medium [500 - 1kg] | D23: 1 | E23: New Zealand | F23: Standard | G23: Medium | H23: 500 - 1kg | I23: 26.4 | J23: =I23*(1+J$20) -> 26.928 | K23: =$J23*(1-K$20) -> 25.5816 | L23: =$J23*(1-L$20) -> 21.5424 | M23: =$J23*(1-M$20) -> 20.196 | N23: =$J23*(1-N$20) -> 18.8496 | O23: =$J23*(1-O$20) -> 17.5032
A24: =IF(ISBLANK(D24),"",D24&"-"&E24) -> 1-New Zealand | B24: =IF(ISBLANK(G24),"",A24&"::"&G24) -> 1-New Zealand::Large | C24: =IF(ISBLANK(G24),"",G24&" ["&H24&"]") -> Large [1 - 1.5kg] | D24: 1 | E24: New Zealand | F24: Standard | G24: Large | H24: 1 - 1.5kg | I24: 33.15 | J24: =I24*(1+J$20) -> 33.813 | K24: =$J24*(1-K$20) -> 32.12235 | L24: =$J24*(1-L$20) -> 27.0504 | M24: =$J24*(1-M$20) -> 25.35975 | N24: =$J24*(1-N$20) -> 23.6691 | O24: =$J24*(1-O$20) -> 21.97845
D25: 1 | E25: New Zealand | F25: Standard | G25: XLarge | H25: 1.5kg - 2kg | I25: 39.9 | J25: =I25*(1+J$20) -> 40.698 | K25: =$J25*(1-K$20) -> 38.6631 | L25: =$J25*(1-L$20) -> 32.5584 | M25: =$J25*(1-M$20) -> 30.5235 | N25: =$J25*(1-N$20) -> 28.4886 | O25: =$J25*(1-O$20) -> 26.4537
A27: Source | D27: Source | E27: https://auspost.com.au/content/dam/auspost_corp/media/documents/mypost-business-postage-rates-guide.pdf

Sheet BrandCOOs
A1: Brand | B1: Type | C1: Primary Materials / Manufacture | D1: Secondaries
A2: Ada + Lou | C2: Indonesia
A3: Aje | C3: China | D3: India | E3: Malaysia
A4: Arnhem | C4: Indonesia
A5: Auguste | C5: China
A6: Blue Illusion | C6: China
A7: Camilla Franks | C7: India | D7: China
A8: Coven & Co | C8: China | D8: Australia
A9: Fillyboo | C9: Indonesia | D9: India
A10: Free People | C10: China | D10: Vietnam
A11: Ghanda | C11: Australia
A12: Innika Choo [Bali] | C12: Indonesia | D12: Vietnam | E12: Malaysia
A13: Innika Choo [China] | C13: China
A14: Innika Choo [India] | C14: India
A15: Jen's Pirate Booty | C15: Mexico
A16: Kivari | C16: China
A17: Kip & Co | C17: India
A18: Lack of Color | B18: Hats | C18: China
A19: Lele Sadoughi | B19: Headbands | C19: United States
A20: Love Bonfire | C20: China
A21: LoveShackFancy | C21: China | D21: India
A22: Nine Lives Bazaar | C22: China
A23: Reebok x Maison | B23: Sneakers | C23: Vietnam
A24: Sabbi | C24: Australia
A25: Selkie | C25: China
A26: Spell | C26: China
A27: Tree of Life | C27: India
A28: Wildfox | B28: Sunnies | C28: China | D28: USA

Sheet USA_Costs
A1: US IEEPA Reciprocal Tariffs | B1: COO | C1: Duty
B2: China | C2: 0.2
B3: Malaysia | C3: 0.19
B4: Indonesia | C4: 0.19
B5: Vietnam | C5: 0.2
B6: Japan | C6: 0.15
B7: India | C7: 0.5
B8: Mexico | C8: 0.25
B9: Australia | C9: 0.1
A11: Zonos Processing Charge | B11: 0.1 | C11: (of duties)
B12: 1.69 | C12: AUD per shipment

Sheet USA_TariffBands
A1: Zone 3 - US & Canada | E1: Country Of Origin/Manufacture (COO)
C2: AusPost Shipping Cost | E2: China | G2: Malaysia Indonesia Vietnam | I2: Australia
A3: Weight Category | B3: Max Value | C3: Band3 | D3: Band4 | E3: Band3 | F3: Band4 | G3: Band3 | H3: Band4 | I3: Band3 | J3: Band4
A4: Small | B4: 100 | C4: =_xlfn.XLOOKUP(A4,PostalCost_International!G:G,PostalCost_International!M:M,"Not Found") -> 24.4035 | D4: =_xlfn.XLOOKUP(A4,PostalCost_International!G:G,PostalCost_International!N:N,"Not Found") -> 23.664 | E4: =IF(NOT(ISBLANK($A4)),$C4+(($B4+$C4)*USA_Costs!$C$2)+((($B4+$C4)*USA_Costs!$C$2)*USA_Costs!$B$11)+USA_Costs!$B$12,"") -> 53.46227 | F4: =IF(NOT(ISBLANK($A4)),$D4+(($B4+$D4)*USA_Costs!$C$2)+((($B4+$D4)*USA_Costs!$C$2)*USA_Costs!$B$11)+USA_Costs!$B$12,"") -> 52.56008 | G4: =IF(NOT(ISBLANK($A4)),$C4+((D4+E4)*USA_Costs!$C$3)+(((D4+E4)*USA_Costs!$C$3)*USA_Costs!$B$11)+USA_Costs!$B$12,"") -> 42.21289 | H4: =IF(NOT(ISBLANK($A4)),$D4+((D4+F4)*USA_Costs!$C$3)+(((D4+F4)*USA_Costs!$C$3)*USA_Costs!$B$11)+USA_Costs!$B$12,"") -> 41.284833 | I4: =IF(NOT(ISBLANK($A4)),$C4+(($B4+$C4)*USA_Costs!$C$9)+((($B4+$C4)*USA_Costs!$C$9)*USA_Costs!$B$11)+USA_Costs!$B$12,"") -> 39.777885 | J4: =IF(NOT(ISBLANK($A4)),$D4+(($B4+$D4)*USA_Costs!$C$9)+((($B4+$D4)*USA_Costs!$C$9)*USA_Costs!$B$11)+USA_Costs!$B$12,"") -> 38.95704
A5: Small | B5: 200 | C5: =_xlfn.XLOOKUP(A5,PostalCost_International!G:G,PostalCost_International!M:M,"Not Found") -> 24.4035 | D5: =_xlfn.XLOOKUP(A5,PostalCost_International!G:G,PostalCost_International!N:N,"Not Found") -> 23.664 | E5: =IF(NOT(ISBLANK($A5)),$C5+(($B5+$C5)*USA_Costs!$C$2)+((($B5+$C5)*USA_Costs!$C$2)*USA_Costs!$B$11)+USA_Costs!$B$12,"") -> 75.46227 | F5: =IF(NOT(ISBLANK($A5)),$D5+(($B5+$D5)*USA_Costs!$C$2)+((($B5+$D5)*USA_Costs!$C$2)*USA_Costs!$B$11)+USA_Costs!$B$12,"") -> 74.56008 | G5: =IF(NOT(ISBLANK($A5)),$C5+((D5+E5)*USA_Costs!$C$3)+(((D5+E5)*USA_Costs!$C$3)*USA_Costs!$B$11)+USA_Costs!$B$12,"") -> 46.81089 | H5: =IF(NOT(ISBLANK($A5)),$D5+((D5+F5)*USA_Costs!$C$3)+(((D5+F5)*USA_Costs!$C$3)*USA_Costs!$B$11)+USA_Costs!$B$12,"") -> 45.882833 | I5: =IF(NOT(ISBLANK($A5)),$C5+(($B5+$C5)*USA_Costs!$C$9)+((($B5+$C5)*USA_Costs!$C$9)*USA_Costs!$B$11)+USA_Costs!$B$12,"") -> 50.777885 | J5: =IF(NOT(ISBLANK($A5)),$D5+(($B5+$D5)*USA_Costs!$C$9)+((($B5+$D5)*USA_Costs!$C$9)*USA_Costs!$B$11)+USA_Costs!$B$12,"") -> 49.95704
A6: Small | B6: 300 | C6: =_xlfn.XLOOKUP(A6,PostalCost_International!G:G,PostalCost_International!M:M,"Not Found") -> 24.4035 | D6: =_xlfn.XLOOKUP(A6,PostalCost_International!G:G,PostalCost_International!N:N,"Not Found") -> 23.664 | E6: =IF(NOT(ISBLANK($A6)),$C6+(($B6+$C6)*USA_Costs!$C$2)+((($B6+$C6)*USA_Costs!$C$2)*USA_Costs!$B$11)+USA_Costs!$B$12,"") -> 97.46227 | F6: =IF(NOT(ISBLANK($A6)),$D6+(($B6+$D6)*USA_Costs!$C$2)+((($B6+$D6)*USA_Costs!$C$2)*USA_Costs!$B$11)+USA_Costs!$B$12,"") -> 96.56008 | G6: =IF(NOT(ISBLANK($A6)),$C6+((D6+E6)*USA_Costs!$C$3)+(((D6+E6)*USA_Costs!$C$3)*USA_Costs!$B$11)+USA_Costs!$B$12,"") -> 51.40889 | H6: =IF(NOT(ISBLANK($A6)),$D6+((D6+F6)*USA_Costs!$C$3)+(((D6+F6)*USA_Costs!$C$3)*USA_Costs!$B$11)+USA_Costs!$B$12,"") -> 50.480833 | I6: =IF(NOT(ISBLANK($A6)),$C6+(($B6+$C6)*USA_Costs!$C$9)+((($B6+$C6)*USA_Costs!$C$9)*USA_Costs!$B$11)+USA_Costs!$B$12,"") -> 61.777885 | J6: =IF(NOT(ISBLANK($A6)),$D6+(($B6+$D6)*USA_Costs!$C$9)+((($B6+$D6)*USA_Costs!$C$9)*USA_Costs!$B$11)+USA_Costs!$B$12,"") -> 60.95704
A7: Small | B7: 400 | C7: =_xlfn.XLOOKUP(A7,PostalCost_International!G:G,PostalCost_International!M:M,"Not Found") -> 24.4035 | D7: =_xlfn.XLOOKUP(A7,PostalCost_International!G:G,PostalCost_International!N:N,"Not Found") -> 23.664 | E7: =IF(NOT(ISBLANK($A7)),$C7+(($B7+$C7)*USA_Costs!$C$2)+((($B7+$C7)*USA_Costs!$C$2)*USA_Costs!$B$11)+USA_Costs!$B$12,"") -> 119.46227 | F7: =IF(NOT(ISBLANK($A7)),$D7+(($B7+$D7)*USA_Costs!$C$2)+((($B7+$D7)*USA_Costs!$C$2)*USA_Costs!$B$11)+USA_Costs!$B$12,"") -> 118.56008 | G7: =IF(NOT(ISBLANK($A7)),$C7+((D7+E7)*USA_Costs!$C$3)+(((D7+E7)*USA_Costs!$C$3)*USA_Costs!$B$11)+USA_Costs!$B$12,"") -> 56.00689 | H7: =IF(NOT(ISBLANK($A7)),$D7+((D7+F7)*USA_Costs!$C$3)+(((D7+F7)*USA_Costs!$C$3)*USA_Costs!$B$11)+USA_Costs!$B$12,"") -> 55.078833 | I7: =IF(NOT(ISBLANK($A7)),$C7+(($B7+$C7)*USA_Costs!$C$9)+((($B7+$C7)*USA_Costs!$C$9)*USA_Costs!$B$11)+USA_Costs!$B$12,"") -> 72.777885 | J7: =IF(NOT(ISBLANK($A7)),$D7+(($B7+$D7)*USA_Costs!$C$9)+((($B7+$D7)*USA_Costs!$C$9)*USA_Costs!$B$11)+USA_Costs!$B$12,"") -> 71.95704
A8: Small | B8: 500 | C8: =_xlfn.XLOOKUP(A8,PostalCost_International!G:G,PostalCost_International!M:M,"Not Found") -> 24.4035 | D8: =_xlfn.XLOOKUP(A8,PostalCost_International!G:G,PostalCost_International!N:N,"Not Found") -> 23.664 | E8: =IF(NOT(ISBLANK($A8)),$C8+(($B8+$C8)*USA_Costs!$C$2)+((($B8+$C8)*USA_Costs!$C$2)*USA_Costs!$B$11)+USA_Costs!$B$12,"") -> 141.46227 | F8: =IF(NOT(ISBLANK($A8)),$D8+(($B8+$D8)*USA_Costs!$C$2)+((($B8+$D8)*USA_Costs!$C$2)*USA_Costs!$B$11)+USA_Costs!$B$12,"") -> 140.56008 | G8: =IF(NOT(ISBLANK($A8)),$C8+((D8+E8)*USA_Costs!$C$3)+(((D8+E8)*USA_Costs!$C$3)*USA_Costs!$B$11)+USA_Costs!$B$12,"") -> 60.60489 | H8: =IF(NOT(ISBLANK($A8)),$D8+((D8+F8)*USA_Costs!$C$3)+(((D8+F8)*USA_Costs!$C$3)*USA_Costs!$B$11)+USA_Costs!$B$12,"") -> 59.676833 | I8: =IF(NOT(ISBLANK($A8)),$C8+(($B8+$C8)*USA_Costs!$C$9)+((($B8+$C8)*USA_Costs!$C$9)*USA_Costs!$B$11)+USA_Costs!$B$12,"") -> 83.777885 | J8: =IF(NOT(ISBLANK($A8)),$D8+(($B8+$D8)*USA_Costs!$C$9)+((($B8+$D8)*USA_Costs!$C$9)*USA_Costs!$B$11)+USA_Costs!$B$12,"") -> 82.95704
A9: Small | B9: 600 | C9: =_xlfn.XLOOKUP(A9,PostalCost_International!G:G,PostalCost_International!M:M,"Not Found") -> 24.4035 | D9: =_xlfn.XLOOKUP(A9,PostalCost_International!G:G,PostalCost_International!N:N,"Not Found") -> 23.664 | E9: =IF(NOT(ISBLANK($A9)),$C9+(($B9+$C9)*USA_Costs!$C$2)+((($B9+$C9)*USA_Costs!$C$2)*USA_Costs!$B$11)+USA_Costs!$B$12,"") -> 163.46227 | F9: =IF(NOT(ISBLANK($A9)),$D9+(($B9+$D9)*USA_Costs!$C$2)+((($B9+$D9)*USA_Costs!$C$2)*USA_Costs!$B$11)+USA_Costs!$B$12,"") -> 162.56008 | G9: =IF(NOT(ISBLANK($A9)),$C9+((D9+E9)*USA_Costs!$C$3)+(((D9+E9)*USA_Costs!$C$3)*USA_Costs!$B$11)+USA_Costs!$B$12,"") -> 65.20289 | H9: =IF(NOT(ISBLANK($A9)),$D9+((D9+F9)*USA_Costs!$C$3)+(((D9+F9)*USA_Costs!$C$3)*USA_Costs!$B$11)+USA_Costs!$B$12,"") -> 64.274833 | I9: =IF(NOT(ISBLANK($A9)),$C9+(($B9+$C9)*USA_Costs!$C$9)+((($B9+$C9)*USA_Costs!$C$9)*USA_Costs!$B$11)+USA_Costs!$B$12,"") -> 94.777885 | J9: =IF(NOT(ISBLANK($A9)),$D9+(($B9+$D9)*USA_Costs!$C$9)+((($B9+$D9)*USA_Costs!$C$9)*USA_Costs!$B$11)+USA_Costs!$B$12,"") -> 93.95704
A10: Small | B10: 700 | C10: =_xlfn.XLOOKUP(A10,PostalCost_International!G:G,PostalCost_International!M:M,"Not Found") -> 24.4035 | D10: =_xlfn.XLOOKUP(A10,PostalCost_International!G:G,PostalCost_International!N:N,"Not Found") -> 23.664 | E10: =IF(NOT(ISBLANK($A10)),$C10+(($B10+$C10)*USA_Costs!$C$2)+((($B10+$C10)*USA_Costs!$C$2)*USA_Costs!$B$11)+USA_Costs!$B$12,"") -> 185.46227 | F10: =IF(NOT(ISBLANK($A10)),$D10+(($B10+$D10)*USA_Costs!$C$2)+((($B10+$D10)*USA_Costs!$C$2)*USA_Costs!$B$11)+USA_Costs!$B$12,"") -> 184.56008 | G10: =IF(NOT(ISBLANK($A10)),$C10+((D10+E10)*USA_Costs!$C$3)+(((D10+E10)*USA_Costs!$C$3)*USA_Costs!$B$11)+USA_Costs!$B$12,"") -> 69.80089 | H10: =IF(NOT(ISBLANK($A10)),$D10+((D10+F10)*USA_Costs!$C$3)+(((D10+F10)*USA_Costs!$C$3)*USA_Costs!$B$11)+USA_Costs!$B$12,"") -> 68.872833 | I10: =IF(NOT(ISBLANK($A10)),$C10+(($B10+$C10)*USA_Costs!$C$9)+((($B10+$C10)*USA_Costs!$C$9)*USA_Costs!$B$11)+USA_Costs!$B$12,"") -> 105.77788 | J10: =IF(NOT(ISBLANK($A10)),$D10+(($B10+$D10)*USA_Costs!$C$9)+((($B10+$D10)*USA_Costs!$C$9)*USA_Costs!$B$11)+USA_Costs!$B$12,"") -> 104.95704
A11: Small | B11: 800 | C11: =_xlfn.XLOOKUP(A11,PostalCost_International!G:G,PostalCost_International!M:M,"Not Found") -> 24.4035 | D11: =_xlfn.XLOOKUP(A11,PostalCost_International!G:G,PostalCost_International!N:N,"Not Found") -> 23.664 | E11: =IF(NOT(ISBLANK($A11)),$C11+(($B11+$C11)*USA_Costs!$C$2)+((($B11+$C11)*USA_Costs!$C$2)*USA_Costs!$B$11)+USA_Costs!$B$12,"") -> 207.46227 | F11: =IF(NOT(ISBLANK($A11)),$D11+(($B11+$D11)*USA_Costs!$C$2)+((($B11+$D11)*USA_Costs!$C$2)*USA_Costs!$B$11)+USA_Costs!$B$12,"") -> 206.56008 | G11: =IF(NOT(ISBLANK($A11)),$C11+((D11+E11)*USA_Costs!$C$3)+(((D11+E11)*USA_Costs!$C$3)*USA_Costs!$B$11)+USA_Costs!$B$12,"") -> 74.39889 | H11: =IF(NOT(ISBLANK($A11)),$D11+((D11+F11)*USA_Costs!$C$3)+(((D11+F11)*USA_Costs!$C$3)*USA_Costs!$B$11)+USA_Costs!$B$12,"") -> 73.470833 | I11: =IF(NOT(ISBLANK($A11)),$C11+(($B11+$C11)*USA_Costs!$C$9)+((($B11+$C11)*USA_Costs!$C$9)*USA_Costs!$B$11)+USA_Costs!$B$12,"") -> 116.77788 | J11: =IF(NOT(ISBLANK($A11)),$D11+(($B11+$D11)*USA_Costs!$C$9)+((($B11+$D11)*USA_Costs!$C$9)*USA_Costs!$B$11)+USA_Costs!$B$12,"") -> 115.95704
A12: Small | B12: 900 | C12: =_xlfn.XLOOKUP(A12,PostalCost_International!G:G,PostalCost_International!M:M,"Not Found") -> 24.4035 | D12: =_xlfn.XLOOKUP(A12,PostalCost_International!G:G,PostalCost_International!N:N,"Not Found") -> 23.664 | E12: =IF(NOT(ISBLANK($A12)),$C12+(($B12+$C12)*USA_Costs!$C$2)+((($B12+$C12)*USA_Costs!$C$2)*USA_Costs!$B$11)+USA_Costs!$B$12,"") -> 229.46227 | F12: =IF(NOT(ISBLANK($A12)),$D12+(($B12+$D12)*USA_Costs!$C$2)+((($B12+$D12)*USA_Costs!$C$2)*USA_Costs!$B$11)+USA_Costs!$B$12,"") -> 228.56008 | G12: =IF(NOT(ISBLANK($A12)),$C12+((D12+E12)*USA_Costs!$C$3)+(((D12+E12)*USA_Costs!$C$3)*USA_Costs!$B$11)+USA_Costs!$B$12,"") -> 78.99689 | H12: =IF(NOT(ISBLANK($A12)),$D12+((D12+F12)*USA_Costs!$C$3)+(((D12+F12)*USA_Costs!$C$3)*USA_Costs!$B$11)+USA_Costs!$B$12,"") -> 78.068833 | I12: =IF(NOT(ISBLANK($A12)),$C12+(($B12+$C12)*USA_Costs!$C$9)+((($B12+$C12)*USA_Costs!$C$9)*USA_Costs!$B$11)+USA_Costs!$B$12,"") -> 127.77788 | J12: =IF(NOT(ISBLANK($A12)),$D12+(($B12+$D12)*USA_Costs!$C$9)+((($B12+$D12)*USA_Costs!$C$9)*USA_Costs!$B$11)+USA_Costs!$B$12,"") -> 126.95704
A13: Small | B13: 1000 | C13: =_xlfn.XLOOKUP(A13,PostalCost_International!G:G,PostalCost_International!M:M,"Not Found") -> 24.4035 | D13: =_xlfn.XLOOKUP(A13,PostalCost_International!G:G,PostalCost_International!N:N,"Not Found") -> 23.664 | E13: =IF(NOT(ISBLANK($A13)),$C13+(($B13+$C13)*USA_Costs!$C$2)+((($B13+$C13)*USA_Costs!$C$2)*USA_Costs!$B$11)+USA_Costs!$B$12,"") -> 251.46227 | F13: =IF(NOT(ISBLANK($A13)),$D13+(($B13+$D13)*USA_Costs!$C$2)+((($B13+$D13)*USA_Costs!$C$2)*USA_Costs!$B$11)+USA_Costs!$B$12,"") -> 250.56008 | G13: =IF(NOT(ISBLANK($A13)),$C13+((D13+E13)*USA_Costs!$C$3)+(((D13+E13)*USA_Costs!$C$3)*USA_Costs!$B$11)+USA_Costs!$B$12,"") -> 83.59489 | H13: =IF(NOT(ISBLANK($A13)),$D13+((D13+F13)*USA_Costs!$C$3)+(((D13+F13)*USA_Costs!$C$3)*USA_Costs!$B$11)+USA_Costs!$B$12,"") -> 82.666833 | I13: =IF(NOT(ISBLANK($A13)),$C13+(($B13+$C13)*USA_Costs!$C$9)+((($B13+$C13)*USA_Costs!$C$9)*USA_Costs!$B$11)+USA_Costs!$B$12,"") -> 138.77788 | J13: =IF(NOT(ISBLANK($A13)),$D13+(($B13+$D13)*USA_Costs!$C$9)+((($B13+$D13)*USA_Costs!$C$9)*USA_Costs!$B$11)+USA_Costs!$B$12,"") -> 137.95704
E14: =IF(NOT(ISBLANK($A14)),$C14+(($B14+$C14)*USA_Costs!$C$2)+((($B14+$C14)*USA_Costs!$C$2)*USA_Costs!$B$11)+USA_Costs!$B$12,"") | F14: =IF(NOT(ISBLANK($A14)),$D14+(($B14+$D14)*USA_Costs!$C$2)+((($B14+$D14)*USA_Costs!$C$2)*USA_Costs!$B$11)+USA_Costs!$B$12,"") | G14: =IF(NOT(ISBLANK($A14)),$C14+((D14+E14)*USA_Costs!$C$3)+(((D14+E14)*USA_Costs!$C$3)*USA_Costs!$B$11)+USA_Costs!$B$12,"") | H14: =IF(NOT(ISBLANK($A14)),$D14+((D14+F14)*USA_Costs!$C$3)+(((D14+F14)*USA_Costs!$C$3)*USA_Costs!$B$11)+USA_Costs!$B$12,"") | I14: =IF(NOT(ISBLANK($A14)),$C14+(($B14+$C14)*USA_Costs!$C$9)+((($B14+$C14)*USA_Costs!$C$9)*USA_Costs!$B$11)+USA_Costs!$B$12,"") | J14: =IF(NOT(ISBLANK($A14)),$D14+(($B14+$D14)*USA_Costs!$C$9)+((($B14+$D14)*USA_Costs!$C$9)*USA_Costs!$B$11)+USA_Costs!$B$12,"")
A15: Medium | B15: 100 | C15: =_xlfn.XLOOKUP(A15,PostalCost_International!G:G,PostalCost_International!M:M,"Not Found") -> 35.5113 | D15: =_xlfn.XLOOKUP(A15,PostalCost_International!G:G,PostalCost_International!N:N,"Not Found") -> 34.4352 | E15: =IF(NOT(ISBLANK($A15)),$C15+(($B15+$C15)*USA_Costs!$C$2)+((($B15+$C15)*USA_Costs!$C$2)*USA_Costs!$B$11)+USA_Costs!$B$12,"") -> 67.013786 | F15: =IF(NOT(ISBLANK($A15)),$D15+(($B15+$D15)*USA_Costs!$C$2)+((($B15+$D15)*USA_Costs!$C$2)*USA_Costs!$B$11)+USA_Costs!$B$12,"") -> 65.700944 | G15: =IF(NOT(ISBLANK($A15)),$C15+(($B15+$C15)*USA_Costs!$C$3)+((($B15+$C15)*USA_Costs!$C$3)*USA_Costs!$B$11)+USA_Costs!$B$12,"") -> 65.523162 | H15: =IF(NOT(ISBLANK($A15)),$D15+(($B15+$D15)*USA_Costs!$C$3)+((($B15+$D15)*USA_Costs!$C$3)*USA_Costs!$B$11)+USA_Costs!$B$12,"") -> 64.222157 | I15: =IF(NOT(ISBLANK($A15)),$C15+(($B15+$C15)*USA_Costs!$C$9)+((($B15+$C15)*USA_Costs!$C$9)*USA_Costs!$B$11)+USA_Costs!$B$12,"") -> 52.107543 | J15: =IF(NOT(ISBLANK($A15)),$D15+(($B15+$D15)*USA_Costs!$C$9)+((($B15+$D15)*USA_Costs!$C$9)*USA_Costs!$B$11)+USA_Costs!$B$12,"") -> 50.913072
A16: Medium | B16: 200 | C16: =_xlfn.XLOOKUP(A16,PostalCost_International!G:G,PostalCost_International!M:M,"Not Found") -> 35.5113 | D16: =_xlfn.XLOOKUP(A16,PostalCost_International!G:G,PostalCost_International!N:N,"Not Found") -> 34.4352 | E16: =IF(NOT(ISBLANK($A16)),$C16+(($B16+$C16)*USA_Costs!$C$2)+((($B16+$C16)*USA_Costs!$C$2)*USA_Costs!$B$11)+USA_Costs!$B$12,"") -> 89.013786 | F16: =IF(NOT(ISBLANK($A16)),$D16+(($B16+$D16)*USA_Costs!$C$2)+((($B16+$D16)*USA_Costs!$C$2)*USA_Costs!$B$11)+USA_Costs!$B$12,"") -> 87.700944 | G16: =IF(NOT(ISBLANK($A16)),$C16+(($B16+$C16)*USA_Costs!$C$3)+((($B16+$C16)*USA_Costs!$C$3)*USA_Costs!$B$11)+USA_Costs!$B$12,"") -> 86.423162 | H16: =IF(NOT(ISBLANK($A16)),$D16+(($B16+$D16)*USA_Costs!$C$3)+((($B16+$D16)*USA_Costs!$C$3)*USA_Costs!$B$11)+USA_Costs!$B$12,"") -> 85.122157 | I16: =IF(NOT(ISBLANK($A16)),$C16+(($B16+$C16)*USA_Costs!$C$9)+((($B16+$C16)*USA_Costs!$C$9)*USA_Costs!$B$11)+USA_Costs!$B$12,"") -> 63.107543 | J16: =IF(NOT(ISBLANK($A16)),$D16+(($B16+$D16)*USA_Costs!$C$9)+((($B16+$D16)*USA_Costs!$C$9)*USA_Costs!$B$11)+USA_Costs!$B$12,"") -> 61.913072
A17: Medium | B17: 300 | C17: =_xlfn.XLOOKUP(A17,PostalCost_International!G:G,PostalCost_International!M:M,"Not Found") -> 35.5113 | D17: =_xlfn.XLOOKUP(A17,PostalCost_International!G:G,PostalCost_International!N:N,"Not Found") -> 34.4352 | E17: =IF(NOT(ISBLANK($A17)),$C17+(($B17+$C17)*USA_Costs!$C$2)+((($B17+$C17)*USA_Costs!$C$2)*USA_Costs!$B$11)+USA_Costs!$B$12,"") -> 111.01379 | F17: =IF(NOT(ISBLANK($A17)),$D17+(($B17+$D17)*USA_Costs!$C$2)+((($B17+$D17)*USA_Costs!$C$2)*USA_Costs!$B$11)+USA_Costs!$B$12,"") -> 109.70094 | G17: =IF(NOT(ISBLANK($A17)),$C17+(($B17+$C17)*USA_Costs!$C$3)+((($B17+$C17)*USA_Costs!$C$3)*USA_Costs!$B$11)+USA_Costs!$B$12,"") -> 107.32316 | H17: =IF(NOT(ISBLANK($A17)),$D17+(($B17+$D17)*USA_Costs!$C$3)+((($B17+$D17)*USA_Costs!$C$3)*USA_Costs!$B$11)+USA_Costs!$B$12,"") -> 106.02216 | I17: =IF(NOT(ISBLANK($A17)),$C17+(($B17+$C17)*USA_Costs!$C$9)+((($B17+$C17)*USA_Costs!$C$9)*USA_Costs!$B$11)+USA_Costs!$B$12,"") -> 74.107543 | J17: =IF(NOT(ISBLANK($A17)),$D17+(($B17+$D17)*USA_Costs!$C$9)+((($B17+$D17)*USA_Costs!$C$9)*USA_Costs!$B$11)+USA_Costs!$B$12,"") -> 72.913072
A18: Medium | B18: 400 | C18: =_xlfn.XLOOKUP(A18,PostalCost_International!G:G,PostalCost_International!M:M,"Not Found") -> 35.5113 | D18: =_xlfn.XLOOKUP(A18,PostalCost_International!G:G,PostalCost_International!N:N,"Not Found") -> 34.4352 | E18: =IF(NOT(ISBLANK($A18)),$C18+(($B18+$C18)*USA_Costs!$C$2)+((($B18+$C18)*USA_Costs!$C$2)*USA_Costs!$B$11)+USA_Costs!$B$12,"") -> 133.01379 | F18: =IF(NOT(ISBLANK($A18)),$D18+(($B18+$D18)*USA_Costs!$C$2)+((($B18+$D18)*USA_Costs!$C$2)*USA_Costs!$B$11)+USA_Costs!$B$12,"") -> 131.70094 | G18: =IF(NOT(ISBLANK($A18)),$C18+(($B18+$C18)*USA_Costs!$C$3)+((($B18+$C18)*USA_Costs!$C$3)*USA_Costs!$B$11)+USA_Costs!$B$12,"") -> 128.22316 | H18: =IF(NOT(ISBLANK($A18)),$D18+(($B18+$D18)*USA_Costs!$C$3)+((($B18+$D18)*USA_Costs!$C$3)*USA_Costs!$B$11)+USA_Costs!$B$12,"") -> 126.92216 | I18: =IF(NOT(ISBLANK($A18)),$C18+(($B18+$C18)*USA_Costs!$C$9)+((($B18+$C18)*USA_Costs!$C$9)*USA_Costs!$B$11)+USA_Costs!$B$12,"") -> 85.107543 | J18: =IF(NOT(ISBLANK($A18)),$D18+(($B18+$D18)*USA_Costs!$C$9)+((($B18+$D18)*USA_Costs!$C$9)*USA_Costs!$B$11)+USA_Costs!$B$12,"") -> 83.913072
A19: Medium | B19: 500 | C19: =_xlfn.XLOOKUP(A19,PostalCost_International!G:G,PostalCost_International!M:M,"Not Found") -> 35.5113 | D19: =_xlfn.XLOOKUP(A19,PostalCost_International!G:G,PostalCost_International!N:N,"Not Found") -> 34.4352 | E19: =IF(NOT(ISBLANK($A19)),$C19+(($B19+$C19)*USA_Costs!$C$2)+((($B19+$C19)*USA_Costs!$C$2)*USA_Costs!$B$11)+USA_Costs!$B$12,"") -> 155.01379 | F19: =IF(NOT(ISBLANK($A19)),$D19+(($B19+$D19)*USA_Costs!$C$2)+((($B19+$D19)*USA_Costs!$C$2)*USA_Costs!$B$11)+USA_Costs!$B$12,"") -> 153.70094 | G19: =IF(NOT(ISBLANK($A19)),$C19+(($B19+$C19)*USA_Costs!$C$3)+((($B19+$C19)*USA_Costs!$C$3)*USA_Costs!$B$11)+USA_Costs!$B$12,"") -> 149.12316 | H19: =IF(NOT(ISBLANK($A19)),$D19+(($B19+$D19)*USA_Costs!$C$3)+((($B19+$D19)*USA_Costs!$C$3)*USA_Costs!$B$11)+USA_Costs!$B$12,"") -> 147.82216 | I19: =IF(NOT(ISBLANK($A19)),$C19+(($B19+$C19)*USA_Costs!$C$9)+((($B19+$C19)*USA_Costs!$C$9)*USA_Costs!$B$11)+USA_Costs!$B$12,"") -> 96.107543 | J19: =IF(NOT(ISBLANK($A19)),$D19+(($B19+$D19)*USA_Costs!$C$9)+((($B19+$D19)*USA_Costs!$C$9)*USA_Costs!$B$11)+USA_Costs!$B$12,"") -> 94.913072
A20: Medium | B20: 600 | C20: =_xlfn.XLOOKUP(A20,PostalCost_International!G:G,PostalCost_International!M:M,"Not Found") -> 35.5113 | D20: =_xlfn.XLOOKUP(A20,PostalCost_International!G:G,PostalCost_International!N:N,"Not Found") -> 34.4352 | E20: =IF(NOT(ISBLANK($A20)),$C20+(($B20+$C20)*USA_Costs!$C$2)+((($B20+$C20)*USA_Costs!$C$2)*USA_Costs!$B$11)+USA_Costs!$B$12,"") -> 177.01379 | F20: =IF(NOT(ISBLANK($A20)),$D20+(($B20+$D20)*USA_Costs!$C$2)+((($B20+$D20)*USA_Costs!$C$2)*USA_Costs!$B$11)+USA_Costs!$B$12,"") -> 175.70094 | G20: =IF(NOT(ISBLANK($A20)),$C20+(($B20+$C20)*USA_Costs!$C$3)+((($B20+$C20)*USA_Costs!$C$3)*USA_Costs!$B$11)+USA_Costs!$B$12,"") -> 170.02316 | H20: =IF(NOT(ISBLANK($A20)),$D20+(($B20+$D20)*USA_Costs!$C$3)+((($B20+$D20)*USA_Costs!$C$3)*USA_Costs!$B$11)+USA_Costs!$B$12,"") -> 168.72216 | I20: =IF(NOT(ISBLANK($A20)),$C20+(($B20+$C20)*USA_Costs!$C$9)+((($B20+$C20)*USA_Costs!$C$9)*USA_Costs!$B$11)+USA_Costs!$B$12,"") -> 107.10754 | J20: =IF(NOT(ISBLANK($A20)),$D20+(($B20+$D20)*USA_Costs!$C$9)+((($B20+$D20)*USA_Costs!$C$9)*USA_Costs!$B$11)+USA_Costs!$B$12,"") -> 105.91307
A21: Medium | B21: 700 | C21: =_xlfn.XLOOKUP(A21,PostalCost_International!G:G,PostalCost_International!M:M,"Not Found") -> 35.5113 | D21: =_xlfn.XLOOKUP(A21,PostalCost_International!G:G,PostalCost_International!N:N,"Not Found") -> 34.4352 | E21: =IF(NOT(ISBLANK($A21)),$C21+(($B21+$C21)*USA_Costs!$C$2)+((($B21+$C21)*USA_Costs!$C$2)*USA_Costs!$B$11)+USA_Costs!$B$12,"") -> 199.01379 | F21: =IF(NOT(ISBLANK($A21)),$D21+(($B21+$D21)*USA_Costs!$C$2)+((($B21+$D21)*USA_Costs!$C$2)*USA_Costs!$B$11)+USA_Costs!$B$12,"") -> 197.70094 | G21: =IF(NOT(ISBLANK($A21)),$C21+(($B21+$C21)*USA_Costs!$C$3)+((($B21+$C21)*USA_Costs!$C$3)*USA_Costs!$B$11)+USA_Costs!$B$12,"") -> 190.92316 | H21: =IF(NOT(ISBLANK($A21)),$D21+(($B21+$D21)*USA_Costs!$C$3)+((($B21+$D21)*USA_Costs!$C$3)*USA_Costs!$B$11)+USA_Costs!$B$12,"") -> 189.62216 | I21: =IF(NOT(ISBLANK($A21)),$C21+(($B21+$C21)*USA_Costs!$C$9)+((($B21+$C21)*USA_Costs!$C$9)*USA_Costs!$B$11)+USA_Costs!$B$12,"") -> 118.10754 | J21: =IF(NOT(ISBLANK($A21)),$D21+(($B21+$D21)*USA_Costs!$C$9)+((($B21+$D21)*USA_Costs!$C$9)*USA_Costs!$B$11)+USA_Costs!$B$12,"") -> 116.91307
A22: Medium | B22: 800 | C22: =_xlfn.XLOOKUP(A22,PostalCost_International!G:G,PostalCost_International!M:M,"Not Found") -> 35.5113 | D22: =_xlfn.XLOOKUP(A22,PostalCost_International!G:G,PostalCost_International!N:N,"Not Found") -> 34.4352 | E22: =IF(NOT(ISBLANK($A22)),$C22+(($B22+$C22)*USA_Costs!$C$2)+((($B22+$C22)*USA_Costs!$C$2)*USA_Costs!$B$11)+USA_Costs!$B$12,"") -> 221.01379 | F22: =IF(NOT(ISBLANK($A22)),$D22+(($B22+$D22)*USA_Costs!$C$2)+((($B22+$D22)*USA_Costs!$C$2)*USA_Costs!$B$11)+USA_Costs!$B$12,"") -> 219.70094 | G22: =IF(NOT(ISBLANK($A22)),$C22+(($B22+$C22)*USA_Costs!$C$3)+((($B22+$C22)*USA_Costs!$C$3)*USA_Costs!$B$11)+USA_Costs!$B$12,"") -> 211.82316 | H22: =IF(NOT(ISBLANK($A22)),$D22+(($B22+$D22)*USA_Costs!$C$3)+((($B22+$D22)*USA_Costs!$C$3)*USA_Costs!$B$11)+USA_Costs!$B$12,"") -> 210.52216 | I22: =IF(NOT(ISBLANK($A22)),$C22+(($B22+$C22)*USA_Costs!$C$9)+((($B22+$C22)*USA_Costs!$C$9)*USA_Costs!$B$11)+USA_Costs!$B$12,"") -> 129.10754 | J22: =IF(NOT(ISBLANK($A22)),$D22+(($B22+$D22)*USA_Costs!$C$9)+((($B22+$D22)*USA_Costs!$C$9)*USA_Costs!$B$11)+USA_Costs!$B$12,"") -> 127.91307
A23: Medium | B23: 900 | C23: =_xlfn.XLOOKUP(A23,PostalCost_International!G:G,PostalCost_International!M:M,"Not Found") -> 35.5113 | D23: =_xlfn.XLOOKUP(A23,PostalCost_International!G:G,PostalCost_International!N:N,"Not Found") -> 34.4352 | E23: =IF(NOT(ISBLANK($A23)),$C23+(($B23+$C23)*USA_Costs!$C$2)+((($B23+$C23)*USA_Costs!$C$2)*USA_Costs!$B$11)+USA_Costs!$B$12,"") -> 243.01379 | F23: =IF(NOT(ISBLANK($A23)),$D23+(($B23+$D23)*USA_Costs!$C$2)+((($B23+$D23)*USA_Costs!$C$2)*USA_Costs!$B$11)+USA_Costs!$B$12,"") -> 241.70094 | G23: =IF(NOT(ISBLANK($A23)),$C23+(($B23+$C23)*USA_Costs!$C$3)+((($B23+$C23)*USA_Costs!$C$3)*USA_Costs!$B$11)+USA_Costs!$B$12,"") -> 232.72316 | H23: =IF(NOT(ISBLANK($A23)),$D23+(($B23+$D23)*USA_Costs!$C$3)+((($B23+$D23)*USA_Costs!$C$3)*USA_Costs!$B$11)+USA_Costs!$B$12,"") -> 231.42216 | I23: =IF(NOT(ISBLANK($A23)),$C23+(($B23+$C23)*USA_Costs!$C$9)+((($B23+$C23)*USA_Costs!$C$9)*USA_Costs!$B$11)+USA_Costs!$B$12,"") -> 140.10754 | J23: =IF(NOT(ISBLANK($A23)),$D23+(($B23+$D23)*USA_Costs!$C$9)+((($B23+$D23)*USA_Costs!$C$9)*USA_Costs!$B$11)+USA_Costs!$B$12,"") -> 138.91307
A24: Medium | B24: 1000 | C24: =_xlfn.XLOOKUP(A24,PostalCost_International!G:G,PostalCost_International!M:M,"Not Found") -> 35.5113 | D24: =_xlfn.XLOOKUP(A24,PostalCost_International!G:G,PostalCost_International!N:N,"Not Found") -> 34.4352 | E24: =IF(NOT(ISBLANK($A24)),$C24+(($B24+$C24)*USA_Costs!$C$2)+((($B24+$C24)*USA_Costs!$C$2)*USA_Costs!$B$11)+USA_Costs!$B$12,"") -> 265.01379 | F24: =IF(NOT(ISBLANK($A24)),$D24+(($B24+$D24)*USA_Costs!$C$2)+((($B24+$D24)*USA_Costs!$C$2)*USA_Costs!$B$11)+USA_Costs!$B$12,"") -> 263.70094 | G24: =IF(NOT(ISBLANK($A24)),$C24+(($B24+$C24)*USA_Costs!$C$3)+((($B24+$C24)*USA_Costs!$C$3)*USA_Costs!$B$11)+USA_Costs!$B$12,"") -> 253.62316 | H24: =IF(NOT(ISBLANK($A24)),$D24+(($B24+$D24)*USA_Costs!$C$3)+((($B24+$D24)*USA_Costs!$C$3)*USA_Costs!$B$11)+USA_Costs!$B$12,"") -> 252.32216 | I24: =IF(NOT(ISBLANK($A24)),$C24+(($B24+$C24)*USA_Costs!$C$9)+((($B24+$C24)*USA_Costs!$C$9)*USA_Costs!$B$11)+USA_Costs!$B$12,"") -> 151.10754 | J24: =IF(NOT(ISBLANK($A24)),$D24+(($B24+$D24)*USA_Costs!$C$9)+((($B24+$D24)*USA_Costs!$C$9)*USA_Costs!$B$11)+USA_Costs!$B$12,"") -> 149.91307
E25: =IF(NOT(ISBLANK($A25)),$C25+(($B25+$C25)*USA_Costs!$C$2)+((($B25+$C25)*USA_Costs!$C$2)*USA_Costs!$B$11)+USA_Costs!$B$12,"") | F25: =IF(NOT(ISBLANK($A25)),$D25+(($B25+$D25)*USA_Costs!$C$2)+((($B25+$D25)*USA_Costs!$C$2)*USA_Costs!$B$11)+USA_Costs!$B$12,"") | G25: =IF(NOT(ISBLANK($A25)),$C25+(($B25+$C25)*USA_Costs!$C$3)+((($B25+$C25)*USA_Costs!$C$3)*USA_Costs!$B$11)+USA_Costs!$B$12,"") | H25: =IF(NOT(ISBLANK($A25)),$D25+(($B25+$D25)*USA_Costs!$C$3)+((($B25+$D25)*USA_Costs!$C$3)*USA_Costs!$B$11)+USA_Costs!$B$12,"") | I25: =IF(NOT(ISBLANK($A25)),$C25+(($B25+$C25)*USA_Costs!$C$9)+((($B25+$C25)*USA_Costs!$C$9)*USA_Costs!$B$11)+USA_Costs!$B$12,"") | J25: =IF(NOT(ISBLANK($A25)),$D25+(($B25+$D25)*USA_Costs!$C$9)+((($B25+$D25)*USA_Costs!$C$9)*USA_Costs!$B$11)+USA_Costs!$B$12,"")
A26: Large | B26: 100 | C26: =_xlfn.XLOOKUP(A26,PostalCost_International!G:G,PostalCost_International!M:M,"Not Found") -> 46.745325 | D26: =_xlfn.XLOOKUP(A26,PostalCost_International!G:G,PostalCost_International!N:N,"Not Found") -> 45.3288 | E26: =IF(NOT(ISBLANK($A26)),$C26+(($B26+$C26)*USA_Costs!$C$2)+((($B26+$C26)*USA_Costs!$C$2)*USA_Costs!$B$11)+USA_Costs!$B$12,"") -> 80.719296 | F26: =IF(NOT(ISBLANK($A26)),$D26+(($B26+$D26)*USA_Costs!$C$2)+((($B26+$D26)*USA_Costs!$C$2)*USA_Costs!$B$11)+USA_Costs!$B$12,"") -> 78.991136 | G26: =IF(NOT(ISBLANK($A26)),$C26+(($B26+$C26)*USA_Costs!$C$3)+((($B26+$C26)*USA_Costs!$C$3)*USA_Costs!$B$11)+USA_Costs!$B$12,"") -> 79.105098 | H26: =IF(NOT(ISBLANK($A26)),$D26+(($B26+$D26)*USA_Costs!$C$3)+((($B26+$D26)*USA_Costs!$C$3)*USA_Costs!$B$11)+USA_Costs!$B$12,"") -> 77.392519 | I26: =IF(NOT(ISBLANK($A26)),$C26+(($B26+$C26)*USA_Costs!$C$9)+((($B26+$C26)*USA_Costs!$C$9)*USA_Costs!$B$11)+USA_Costs!$B$12,"") -> 64.577311 | J26: =IF(NOT(ISBLANK($A26)),$D26+(($B26+$D26)*USA_Costs!$C$9)+((($B26+$D26)*USA_Costs!$C$9)*USA_Costs!$B$11)+USA_Costs!$B$12,"") -> 63.004968
A27: Large | B27: 200 | C27: =_xlfn.XLOOKUP(A27,PostalCost_International!G:G,PostalCost_International!M:M,"Not Found") -> 46.745325 | D27: =_xlfn.XLOOKUP(A27,PostalCost_International!G:G,PostalCost_International!N:N,"Not Found") -> 45.3288 | E27: =IF(NOT(ISBLANK($A27)),$C27+(($B27+$C27)*USA_Costs!$C$2)+((($B27+$C27)*USA_Costs!$C$2)*USA_Costs!$B$11)+USA_Costs!$B$12,"") -> 102.7193 | F27: =IF(NOT(ISBLANK($A27)),$D27+(($B27+$D27)*USA_Costs!$C$2)+((($B27+$D27)*USA_Costs!$C$2)*USA_Costs!$B$11)+USA_Costs!$B$12,"") -> 100.99114 | G27: =IF(NOT(ISBLANK($A27)),$C27+(($B27+$C27)*USA_Costs!$C$3)+((($B27+$C27)*USA_Costs!$C$3)*USA_Costs!$B$11)+USA_Costs!$B$12,"") -> 100.0051 | H27: =IF(NOT(ISBLANK($A27)),$D27+(($B27+$D27)*USA_Costs!$C$3)+((($B27+$D27)*USA_Costs!$C$3)*USA_Costs!$B$11)+USA_Costs!$B$12,"") -> 98.292519 | I27: =IF(NOT(ISBLANK($A27)),$C27+(($B27+$C27)*USA_Costs!$C$9)+((($B27+$C27)*USA_Costs!$C$9)*USA_Costs!$B$11)+USA_Costs!$B$12,"") -> 75.577311 | J27: =IF(NOT(ISBLANK($A27)),$D27+(($B27+$D27)*USA_Costs!$C$9)+((($B27+$D27)*USA_Costs!$C$9)*USA_Costs!$B$11)+USA_Costs!$B$12,"") -> 74.004968
A28: Large | B28: 300 | C28: =_xlfn.XLOOKUP(A28,PostalCost_International!G:G,PostalCost_International!M:M,"Not Found") -> 46.745325 | D28: =_xlfn.XLOOKUP(A28,PostalCost_International!G:G,PostalCost_International!N:N,"Not Found") -> 45.3288 | E28: =IF(NOT(ISBLANK($A28)),$C28+(($B28+$C28)*USA_Costs!$C$2)+((($B28+$C28)*USA_Costs!$C$2)*USA_Costs!$B$11)+USA_Costs!$B$12,"") -> 124.7193 | F28: =IF(NOT(ISBLANK($A28)),$D28+(($B28+$D28)*USA_Costs!$C$2)+((($B28+$D28)*USA_Costs!$C$2)*USA_Costs!$B$11)+USA_Costs!$B$12,"") -> 122.99114 | G28: =IF(NOT(ISBLANK($A28)),$C28+(($B28+$C28)*USA_Costs!$C$3)+((($B28+$C28)*USA_Costs!$C$3)*USA_Costs!$B$11)+USA_Costs!$B$12,"") -> 120.9051 | H28: =IF(NOT(ISBLANK($A28)),$D28+(($B28+$D28)*USA_Costs!$C$3)+((($B28+$D28)*USA_Costs!$C$3)*USA_Costs!$B$11)+USA_Costs!$B$12,"") -> 119.19252 | I28: =IF(NOT(ISBLANK($A28)),$C28+(($B28+$C28)*USA_Costs!$C$9)+((($B28+$C28)*USA_Costs!$C$9)*USA_Costs!$B$11)+USA_Costs!$B$12,"") -> 86.577311 | J28: =IF(NOT(ISBLANK($A28)),$D28+(($B28+$D28)*USA_Costs!$C$9)+((($B28+$D28)*USA_Costs!$C$9)*USA_Costs!$B$11)+USA_Costs!$B$12,"") -> 85.004968
A29: Large | B29: 400 | C29: =_xlfn.XLOOKUP(A29,PostalCost_International!G:G,PostalCost_International!M:M,"Not Found") -> 46.745325 | D29: =_xlfn.XLOOKUP(A29,PostalCost_International!G:G,PostalCost_International!N:N,"Not Found") -> 45.3288 | E29: =IF(NOT(ISBLANK($A29)),$C29+(($B29+$C29)*USA_Costs!$C$2)+((($B29+$C29)*USA_Costs!$C$2)*USA_Costs!$B$11)+USA_Costs!$B$12,"") -> 146.7193 | F29: =IF(NOT(ISBLANK($A29)),$D29+(($B29+$D29)*USA_Costs!$C$2)+((($B29+$D29)*USA_Costs!$C$2)*USA_Costs!$B$11)+USA_Costs!$B$12,"") -> 144.99114 | G29: =IF(NOT(ISBLANK($A29)),$C29+(($B29+$C29)*USA_Costs!$C$3)+((($B29+$C29)*USA_Costs!$C$3)*USA_Costs!$B$11)+USA_Costs!$B$12,"") -> 141.8051 | H29: =IF(NOT(ISBLANK($A29)),$D29+(($B29+$D29)*USA_Costs!$C$3)+((($B29+$D29)*USA_Costs!$C$3)*USA_Costs!$B$11)+USA_Costs!$B$12,"") -> 140.09252 | I29: =IF(NOT(ISBLANK($A29)),$C29+(($B29+$C29)*USA_Costs!$C$9)+((($B29+$C29)*USA_Costs!$C$9)*USA_Costs!$B$11)+USA_Costs!$B$12,"") -> 97.577311 | J29: =IF(NOT(ISBLANK($A29)),$D29+(($B29+$D29)*USA_Costs!$C$9)+((($B29+$D29)*USA_Costs!$C$9)*USA_Costs!$B$11)+USA_Costs!$B$12,"") -> 96.004968
A30: Large | B30: 500 | C30: =_xlfn.XLOOKUP(A30,PostalCost_International!G:G,PostalCost_International!M:M,"Not Found") -> 46.745325 | D30: =_xlfn.XLOOKUP(A30,PostalCost_International!G:G,PostalCost_International!N:N,"Not Found") -> 45.3288 | E30: =IF(NOT(ISBLANK($A30)),$C30+(($B30+$C30)*USA_Costs!$C$2)+((($B30+$C30)*USA_Costs!$C$2)*USA_Costs!$B$11)+USA_Costs!$B$12,"") -> 168.7193 | F30: =IF(NOT(ISBLANK($A30)),$D30+(($B30+$D30)*USA_Costs!$C$2)+((($B30+$D30)*USA_Costs!$C$2)*USA_Costs!$B$11)+USA_Costs!$B$12,"") -> 166.99114 | G30: =IF(NOT(ISBLANK($A30)),$C30+(($B30+$C30)*USA_Costs!$C$3)+((($B30+$C30)*USA_Costs!$C$3)*USA_Costs!$B$11)+USA_Costs!$B$12,"") -> 162.7051 | H30: =IF(NOT(ISBLANK($A30)),$D30+(($B30+$D30)*USA_Costs!$C$3)+((($B30+$D30)*USA_Costs!$C$3)*USA_Costs!$B$11)+USA_Costs!$B$12,"") -> 160.99252 | I30: =IF(NOT(ISBLANK($A30)),$C30+(($B30+$C30)*USA_Costs!$C$9)+((($B30+$C30)*USA_Costs!$C$9)*USA_Costs!$B$11)+USA_Costs!$B$12,"") -> 108.57731 | J30: =IF(NOT(ISBLANK($A30)),$D30+(($B30+$D30)*USA_Costs!$C$9)+((($B30+$D30)*USA_Costs!$C$9)*USA_Costs!$B$11)+USA_Costs!$B$12,"") -> 107.00497
A31: Large | B31: 600 | C31: =_xlfn.XLOOKUP(A31,PostalCost_International!G:G,PostalCost_International!M:M,"Not Found") -> 46.745325 | D31: =_xlfn.XLOOKUP(A31,PostalCost_International!G:G,PostalCost_International!N:N,"Not Found") -> 45.3288 | E31: =IF(NOT(ISBLANK($A31)),$C31+(($B31+$C31)*USA_Costs!$C$2)+((($B31+$C31)*USA_Costs!$C$2)*USA_Costs!$B$11)+USA_Costs!$B$12,"") -> 190.7193 | F31: =IF(NOT(ISBLANK($A31)),$D31+(($B31+$D31)*USA_Costs!$C$2)+((($B31+$D31)*USA_Costs!$C$2)*USA_Costs!$B$11)+USA_Costs!$B$12,"") -> 188.99114 | G31: =IF(NOT(ISBLANK($A31)),$C31+(($B31+$C31)*USA_Costs!$C$3)+((($B31+$C31)*USA_Costs!$C$3)*USA_Costs!$B$11)+USA_Costs!$B$12,"") -> 183.6051 | H31: =IF(NOT(ISBLANK($A31)),$D31+(($B31+$D31)*USA_Costs!$C$3)+((($B31+$D31)*USA_Costs!$C$3)*USA_Costs!$B$11)+USA_Costs!$B$12,"") -> 181.89252 | I31: =IF(NOT(ISBLANK($A31)),$C31+(($B31+$C31)*USA_Costs!$C$9)+((($B31+$C31)*USA_Costs!$C$9)*USA_Costs!$B$11)+USA_Costs!$B$12,"") -> 119.57731 | J31: =IF(NOT(ISBLANK($A31)),$D31+(($B31+$D31)*USA_Costs!$C$9)+((($B31+$D31)*USA_Costs!$C$9)*USA_Costs!$B$11)+USA_Costs!$B$12,"") -> 118.00497
A32: Large | B32: 700 | C32: =_xlfn.XLOOKUP(A32,PostalCost_International!G:G,PostalCost_International!M:M,"Not Found") -> 46.745325 | D32: =_xlfn.XLOOKUP(A32,PostalCost_International!G:G,PostalCost_International!N:N,"Not Found") -> 45.3288 | E32: =IF(NOT(ISBLANK($A32)),$C32+(($B32+$C32)*USA_Costs!$C$2)+((($B32+$C32)*USA_Costs!$C$2)*USA_Costs!$B$11)+USA_Costs!$B$12,"") -> 212.7193 | F32: =IF(NOT(ISBLANK($A32)),$D32+(($B32+$D32)*USA_Costs!$C$2)+((($B32+$D32)*USA_Costs!$C$2)*USA_Costs!$B$11)+USA_Costs!$B$12,"") -> 210.99114 | G32: =IF(NOT(ISBLANK($A32)),$C32+(($B32+$C32)*USA_Costs!$C$3)+((($B32+$C32)*USA_Costs!$C$3)*USA_Costs!$B$11)+USA_Costs!$B$12,"") -> 204.5051 | H32: =IF(NOT(ISBLANK($A32)),$D32+(($B32+$D32)*USA_Costs!$C$3)+((($B32+$D32)*USA_Costs!$C$3)*USA_Costs!$B$11)+USA_Costs!$B$12,"") -> 202.79252 | I32: =IF(NOT(ISBLANK($A32)),$C32+(($B32+$C32)*USA_Costs!$C$9)+((($B32+$C32)*USA_Costs!$C$9)*USA_Costs!$B$11)+USA_Costs!$B$12,"") -> 130.57731 | J32: =IF(NOT(ISBLANK($A32)),$D32+(($B32+$D32)*USA_Costs!$C$9)+((($B32+$D32)*USA_Costs!$C$9)*USA_Costs!$B$11)+USA_Costs!$B$12,"") -> 129.00497
A33: Large | B33: 800 | C33: =_xlfn.XLOOKUP(A33,PostalCost_International!G:G,PostalCost_International!M:M,"Not Found") -> 46.745325 | D33: =_xlfn.XLOOKUP(A33,PostalCost_International!G:G,PostalCost_International!N:N,"Not Found") -> 45.3288 | E33: =IF(NOT(ISBLANK($A33)),$C33+(($B33+$C33)*USA_Costs!$C$2)+((($B33+$C33)*USA_Costs!$C$2)*USA_Costs!$B$11)+USA_Costs!$B$12,"") -> 234.7193 | F33: =IF(NOT(ISBLANK($A33)),$D33+(($B33+$D33)*USA_Costs!$C$2)+((($B33+$D33)*USA_Costs!$C$2)*USA_Costs!$B$11)+USA_Costs!$B$12,"") -> 232.99114 | G33: =IF(NOT(ISBLANK($A33)),$C33+(($B33+$C33)*USA_Costs!$C$3)+((($B33+$C33)*USA_Costs!$C$3)*USA_Costs!$B$11)+USA_Costs!$B$12,"") -> 225.4051 | H33: =IF(NOT(ISBLANK($A33)),$D33+(($B33+$D33)*USA_Costs!$C$3)+((($B33+$D33)*USA_Costs!$C$3)*USA_Costs!$B$11)+USA_Costs!$B$12,"") -> 223.69252 | I33: =IF(NOT(ISBLANK($A33)),$C33+(($B33+$C33)*USA_Costs!$C$9)+((($B33+$C33)*USA_Costs!$C$9)*USA_Costs!$B$11)+USA_Costs!$B$12,"") -> 141.57731 | J33: =IF(NOT(ISBLANK($A33)),$D33+(($B33+$D33)*USA_Costs!$C$9)+((($B33+$D33)*USA_Costs!$C$9)*USA_Costs!$B$11)+USA_Costs!$B$12,"") -> 140.00497
A34: Large | B34: 900 | C34: =_xlfn.XLOOKUP(A34,PostalCost_International!G:G,PostalCost_International!M:M,"Not Found") -> 46.745325 | D34: =_xlfn.XLOOKUP(A34,PostalCost_International!G:G,PostalCost_International!N:N,"Not Found") -> 45.3288 | E34: =IF(NOT(ISBLANK($A34)),$C34+(($B34+$C34)*USA_Costs!$C$2)+((($B34+$C34)*USA_Costs!$C$2)*USA_Costs!$B$11)+USA_Costs!$B$12,"") -> 256.7193 | F34: =IF(NOT(ISBLANK($A34)),$D34+(($B34+$D34)*USA_Costs!$C$2)+((($B34+$D34)*USA_Costs!$C$2)*USA_Costs!$B$11)+USA_Costs!$B$12,"") -> 254.99114 | G34: =IF(NOT(ISBLANK($A34)),$C34+(($B34+$C34)*USA_Costs!$C$3)+((($B34+$C34)*USA_Costs!$C$3)*USA_Costs!$B$11)+USA_Costs!$B$12,"") -> 246.3051 | H34: =IF(NOT(ISBLANK($A34)),$D34+(($B34+$D34)*USA_Costs!$C$3)+((($B34+$D34)*USA_Costs!$C$3)*USA_Costs!$B$11)+USA_Costs!$B$12,"") -> 244.59252 | I34: =IF(NOT(ISBLANK($A34)),$C34+(($B34+$C34)*USA_Costs!$C$9)+((($B34+$C34)*USA_Costs!$C$9)*USA_Costs!$B$11)+USA_Costs!$B$12,"") -> 152.57731 | J34: =IF(NOT(ISBLANK($A34)),$D34+(($B34+$D34)*USA_Costs!$C$9)+((($B34+$D34)*USA_Costs!$C$9)*USA_Costs!$B$11)+USA_Costs!$B$12,"") -> 151.00497
A35: Large | B35: 1000 | C35: =_xlfn.XLOOKUP(A35,PostalCost_International!G:G,PostalCost_International!M:M,"Not Found") -> 46.745325 | D35: =_xlfn.XLOOKUP(A35,PostalCost_International!G:G,PostalCost_International!N:N,"Not Found") -> 45.3288 | E35: =IF(NOT(ISBLANK($A35)),$C35+(($B35+$C35)*USA_Costs!$C$2)+((($B35+$C35)*USA_Costs!$C$2)*USA_Costs!$B$11)+USA_Costs!$B$12,"") -> 278.7193 | F35: =IF(NOT(ISBLANK($A35)),$D35+(($B35+$D35)*USA_Costs!$C$2)+((($B35+$D35)*USA_Costs!$C$2)*USA_Costs!$B$11)+USA_Costs!$B$12,"") -> 276.99114 | G35: =IF(NOT(ISBLANK($A35)),$C35+(($B35+$C35)*USA_Costs!$C$3)+((($B35+$C35)*USA_Costs!$C$3)*USA_Costs!$B$11)+USA_Costs!$B$12,"") -> 267.2051 | H35: =IF(NOT(ISBLANK($A35)),$D35+(($B35+$D35)*USA_Costs!$C$3)+((($B35+$D35)*USA_Costs!$C$3)*USA_Costs!$B$11)+USA_Costs!$B$12,"") -> 265.49252 | I35: =IF(NOT(ISBLANK($A35)),$C35+(($B35+$C35)*USA_Costs!$C$9)+((($B35+$C35)*USA_Costs!$C$9)*USA_Costs!$B$11)+USA_Costs!$B$12,"") -> 163.57731 | J35: =IF(NOT(ISBLANK($A35)),$D35+(($B35+$D35)*USA_Costs!$C$9)+((($B35+$D35)*USA_Costs!$C$9)*USA_Costs!$B$11)+USA_Costs!$B$12,"") -> 162.00497
E36: =IF(NOT(ISBLANK($A36)),$C36+(($B36+$C36)*USA_Costs!$C$2)+((($B36+$C36)*USA_Costs!$C$2)*USA_Costs!$B$11)+USA_Costs!$B$12,"") | F36: =IF(NOT(ISBLANK($A36)),$D36+(($B36+$D36)*USA_Costs!$C$2)+((($B36+$D36)*USA_Costs!$C$2)*USA_Costs!$B$11)+USA_Costs!$B$12,"") | G36: =IF(NOT(ISBLANK($A36)),$C36+(($B36+$C36)*USA_Costs!$C$3)+((($B36+$C36)*USA_Costs!$C$3)*USA_Costs!$B$11)+USA_Costs!$B$12,"") | H36: =IF(NOT(ISBLANK($A36)),$D36+(($B36+$D36)*USA_Costs!$C$3)+((($B36+$D36)*USA_Costs!$C$3)*USA_Costs!$B$11)+USA_Costs!$B$12,"") | I36: =IF(NOT(ISBLANK($A36)),$C36+(($B36+$C36)*USA_Costs!$C$9)+((($B36+$C36)*USA_Costs!$C$9)*USA_Costs!$B$11)+USA_Costs!$B$12,"") | J36: =IF(NOT(ISBLANK($A36)),$D36+(($B36+$D36)*USA_Costs!$C$9)+((($B36+$D36)*USA_Costs!$C$9)*USA_Costs!$B$11)+USA_Costs!$B$12,"")
A37: XLarge | B37: 100 | C37: =_xlfn.XLOOKUP(A37,PostalCost_International!G:G,PostalCost_International!M:M,"Not Found") -> 57.937275 | D37: =_xlfn.XLOOKUP(A37,PostalCost_International!G:G,PostalCost_International!N:N,"Not Found") -> 56.1816 | E37: =IF(NOT(ISBLANK($A37)),$C37+(($B37+$C37)*USA_Costs!$C$2)+((($B37+$C37)*USA_Costs!$C$2)*USA_Costs!$B$11)+USA_Costs!$B$12,"") -> 94.373475 | F37: =IF(NOT(ISBLANK($A37)),$D37+(($B37+$D37)*USA_Costs!$C$2)+((($B37+$D37)*USA_Costs!$C$2)*USA_Costs!$B$11)+USA_Costs!$B$12,"") -> 92.231552 | G37: =IF(NOT(ISBLANK($A37)),$C37+(($B37+$C37)*USA_Costs!$C$3)+((($B37+$C37)*USA_Costs!$C$3)*USA_Costs!$B$11)+USA_Costs!$B$12,"") -> 92.636165 | H37: =IF(NOT(ISBLANK($A37)),$D37+(($B37+$D37)*USA_Costs!$C$3)+((($B37+$D37)*USA_Costs!$C$3)*USA_Costs!$B$11)+USA_Costs!$B$12,"") -> 90.513554 | I37: =IF(NOT(ISBLANK($A37)),$C37+(($B37+$C37)*USA_Costs!$C$9)+((($B37+$C37)*USA_Costs!$C$9)*USA_Costs!$B$11)+USA_Costs!$B$12,"") -> 77.000375 | J37: =IF(NOT(ISBLANK($A37)),$D37+(($B37+$D37)*USA_Costs!$C$9)+((($B37+$D37)*USA_Costs!$C$9)*USA_Costs!$B$11)+USA_Costs!$B$12,"") -> 75.051576
A38: XLarge | B38: 200 | C38: =_xlfn.XLOOKUP(A38,PostalCost_International!G:G,PostalCost_International!M:M,"Not Found") -> 57.937275 | D38: =_xlfn.XLOOKUP(A38,PostalCost_International!G:G,PostalCost_International!N:N,"Not Found") -> 56.1816 | E38: =IF(NOT(ISBLANK($A38)),$C38+(($B38+$C38)*USA_Costs!$C$2)+((($B38+$C38)*USA_Costs!$C$2)*USA_Costs!$B$11)+USA_Costs!$B$12,"") -> 116.37348 | F38: =IF(NOT(ISBLANK($A38)),$D38+(($B38+$D38)*USA_Costs!$C$2)+((($B38+$D38)*USA_Costs!$C$2)*USA_Costs!$B$11)+USA_Costs!$B$12,"") -> 114.23155 | G38: =IF(NOT(ISBLANK($A38)),$C38+(($B38+$C38)*USA_Costs!$C$3)+((($B38+$C38)*USA_Costs!$C$3)*USA_Costs!$B$11)+USA_Costs!$B$12,"") -> 113.53617 | H38: =IF(NOT(ISBLANK($A38)),$D38+(($B38+$D38)*USA_Costs!$C$3)+((($B38+$D38)*USA_Costs!$C$3)*USA_Costs!$B$11)+USA_Costs!$B$12,"") -> 111.41355 | I38: =IF(NOT(ISBLANK($A38)),$C38+(($B38+$C38)*USA_Costs!$C$9)+((($B38+$C38)*USA_Costs!$C$9)*USA_Costs!$B$11)+USA_Costs!$B$12,"") -> 88.000375 | J38: =IF(NOT(ISBLANK($A38)),$D38+(($B38+$D38)*USA_Costs!$C$9)+((($B38+$D38)*USA_Costs!$C$9)*USA_Costs!$B$11)+USA_Costs!$B$12,"") -> 86.051576
A39: XLarge | B39: 300 | C39: =_xlfn.XLOOKUP(A39,PostalCost_International!G:G,PostalCost_International!M:M,"Not Found") -> 57.937275 | D39: =_xlfn.XLOOKUP(A39,PostalCost_International!G:G,PostalCost_International!N:N,"Not Found") -> 56.1816 | E39: =IF(NOT(ISBLANK($A39)),$C39+(($B39+$C39)*USA_Costs!$C$2)+((($B39+$C39)*USA_Costs!$C$2)*USA_Costs!$B$11)+USA_Costs!$B$12,"") -> 138.37348 | F39: =IF(NOT(ISBLANK($A39)),$D39+(($B39+$D39)*USA_Costs!$C$2)+((($B39+$D39)*USA_Costs!$C$2)*USA_Costs!$B$11)+USA_Costs!$B$12,"") -> 136.23155 | G39: =IF(NOT(ISBLANK($A39)),$C39+(($B39+$C39)*USA_Costs!$C$3)+((($B39+$C39)*USA_Costs!$C$3)*USA_Costs!$B$11)+USA_Costs!$B$12,"") -> 134.43617 | H39: =IF(NOT(ISBLANK($A39)),$D39+(($B39+$D39)*USA_Costs!$C$3)+((($B39+$D39)*USA_Costs!$C$3)*USA_Costs!$B$11)+USA_Costs!$B$12,"") -> 132.31355 | I39: =IF(NOT(ISBLANK($A39)),$C39+(($B39+$C39)*USA_Costs!$C$9)+((($B39+$C39)*USA_Costs!$C$9)*USA_Costs!$B$11)+USA_Costs!$B$12,"") -> 99.000375 | J39: =IF(NOT(ISBLANK($A39)),$D39+(($B39+$D39)*USA_Costs!$C$9)+((($B39+$D39)*USA_Costs!$C$9)*USA_Costs!$B$11)+USA_Costs!$B$12,"") -> 97.051576
A40: XLarge | B40: 400 | C40: =_xlfn.XLOOKUP(A40,PostalCost_International!G:G,PostalCost_International!M:M,"Not Found") -> 57.937275 | D40: =_xlfn.XLOOKUP(A40,PostalCost_International!G:G,PostalCost_International!N:N,"Not Found") -> 56.1816 | E40: =IF(NOT(ISBLANK($A40)),$C40+(($B40+$C40)*USA_Costs!$C$2)+((($B40+$C40)*USA_Costs!$C$2)*USA_Costs!$B$11)+USA_Costs!$B$12,"") -> 160.37348 | F40: =IF(NOT(ISBLANK($A40)),$D40+(($B40+$D40)*USA_Costs!$C$2)+((($B40+$D40)*USA_Costs!$C$2)*USA_Costs!$B$11)+USA_Costs!$B$12,"") -> 158.23155 | G40: =IF(NOT(ISBLANK($A40)),$C40+(($B40+$C40)*USA_Costs!$C$3)+((($B40+$C40)*USA_Costs!$C$3)*USA_Costs!$B$11)+USA_Costs!$B$12,"") -> 155.33617 | H40: =IF(NOT(ISBLANK($A40)),$D40+(($B40+$D40)*USA_Costs!$C$3)+((($B40+$D40)*USA_Costs!$C$3)*USA_Costs!$B$11)+USA_Costs!$B$12,"") -> 153.21355 | I40: =IF(NOT(ISBLANK($A40)),$C40+(($B40+$C40)*USA_Costs!$C$9)+((($B40+$C40)*USA_Costs!$C$9)*USA_Costs!$B$11)+USA_Costs!$B$12,"") -> 110.00038 | J40: =IF(NOT(ISBLANK($A40)),$D40+(($B40+$D40)*USA_Costs!$C$9)+((($B40+$D40)*USA_Costs!$C$9)*USA_Costs!$B$11)+USA_Costs!$B$12,"") -> 108.05158
...

Sheet Extra Cover
B2: Band 0 (Base) per $100 part thereof | C2: Band 1 | D2: Band 2 | E2: Band 3 | F2: Band 4 | G2: Band 5
B3: 4 | C3: 0.4 | D3: 0.4 | E3: 0.4 | F3: 0.4 | G3: 0.4
B7: Value Less Than | C7: Extra Cover
B8: 100 | C8: =($B8-100)/100*$B$3*(1-C$3) -> 0 | D8: =($B8-100)/100*$B$3*(1-D$3) -> 0 | E8: =($B8-100)/100*$B$3*(1-E$3) -> 0 | F8: =($B8-100)/100*$B$3*(1-F$3) -> 0 | G8: =($B8-100)/100*$B$3*(1-G$3) -> 0
B9: 200 | C9: =($B9-100)/100*$B$3*(1-C$3) -> 2.4 | D9: =($B9-100)/100*$B$3*(1-D$3) -> 2.4 | E9: =($B9-100)/100*$B$3*(1-E$3) -> 2.4 | F9: =($B9-100)/100*$B$3*(1-F$3) -> 2.4 | G9: =($B9-100)/100*$B$3*(1-G$3) -> 2.4
B10: 300 | C10: =($B10-100)/100*$B$3*(1-C$3) -> 4.8 | D10: =($B10-100)/100*$B$3*(1-D$3) -> 4.8 | E10: =($B10-100)/100*$B$3*(1-E$3) -> 4.8 | F10: =($B10-100)/100*$B$3*(1-F$3) -> 4.8 | G10: =($B10-100)/100*$B$3*(1-G$3) -> 4.8
B11: 400 | C11: =($B11-100)/100*$B$3*(1-C$3) -> 7.2 | D11: =($B11-100)/100*$B$3*(1-D$3) -> 7.2 | E11: =($B11-100)/100*$B$3*(1-E$3) -> 7.2 | F11: =($B11-100)/100*$B$3*(1-F$3) -> 7.2 | G11: =($B11-100)/100*$B$3*(1-G$3) -> 7.2
B12: 500 | C12: =($B12-100)/100*$B$3*(1-C$3) -> 9.6 | D12: =($B12-100)/100*$B$3*(1-D$3) -> 9.6 | E12: =($B12-100)/100*$B$3*(1-E$3) -> 9.6 | F12: =($B12-100)/100*$B$3*(1-F$3) -> 9.6 | G12: =($B12-100)/100*$B$3*(1-G$3) -> 9.6
B13: 600 | C13: =($B13-100)/100*$B$3*(1-C$3) -> 12 | D13: =($B13-100)/100*$B$3*(1-D$3) -> 12 | E13: =($B13-100)/100*$B$3*(1-E$3) -> 12 | F13: =($B13-100)/100*$B$3*(1-F$3) -> 12 | G13: =($B13-100)/100*$B$3*(1-G$3) -> 12
B14: 700 | C14: =($B14-100)/100*$B$3*(1-C$3) -> 14.4 | D14: =($B14-100)/100*$B$3*(1-D$3) -> 14.4 | E14: =($B14-100)/100*$B$3*(1-E$3) -> 14.4 | F14: =($B14-100)/100*$B$3*(1-F$3) -> 14.4 | G14: =($B14-100)/100*$B$3*(1-G$3) -> 14.4
B15: 800 | C15: =($B15-100)/100*$B$3*(1-C$3) -> 16.8 | D15: =($B15-100)/100*$B$3*(1-D$3) -> 16.8 | E15: =($B15-100)/100*$B$3*(1-E$3) -> 16.8 | F15: =($B15-100)/100*$B$3*(1-F$3) -> 16.8 | G15: =($B15-100)/100*$B$3*(1-G$3) -> 16.8
B16: 900 | C16: =($B16-100)/100*$B$3*(1-C$3) -> 19.2 | D16: =($B16-100)/100*$B$3*(1-D$3) -> 19.2 | E16: =($B16-100)/100*$B$3*(1-E$3) -> 19.2 | F16: =($B16-100)/100*$B$3*(1-F$3) -> 19.2 | G16: =($B16-100)/100*$B$3*(1-G$3) -> 19.2
B17: 1000 | C17: =($B17-100)/100*$B$3*(1-C$3) -> 21.6 | D17: =($B17-100)/100*$B$3*(1-D$3) -> 21.6 | E17: =($B17-100)/100*$B$3*(1-E$3) -> 21.6 | F17: =($B17-100)/100*$B$3*(1-F$3) -> 21.6 | G17: =($B17-100)/100*$B$3*(1-G$3) -> 21.6
B18: 1100 | C18: =($B18-100)/100*$B$3*(1-C$3) -> 24 | D18: =($B18-100)/100*$B$3*(1-D$3) -> 24 | E18: =($B18-100)/100*$B$3*(1-E$3) -> 24 | F18: =($B18-100)/100*$B$3*(1-F$3) -> 24 | G18: =($B18-100)/100*$B$3*(1-G$3) -> 24
B19: 1200 | C19: =($B19-100)/100*$B$3*(1-C$3) -> 26.4 | D19: =($B19-100)/100*$B$3*(1-D$3) -> 26.4 | E19: =($B19-100)/100*$B$3*(1-E$3) -> 26.4 | F19: =($B19-100)/100*$B$3*(1-F$3) -> 26.4 | G19: =($B19-100)/100*$B$3*(1-G$3) -> 26.4
